<?xml version='1.0'?>
<sdf version='1.4'>
  <model name="en613">
    <static>false</static>
    <link name='chassis'>
      <pose>0 0 0.1 0 0 0</pose>
      <inertial>
        <mass>5.0</mass>
        <inertia>
          <ixx> 0.104167 </ixx>
          <ixy>0</ixy>
          <ixz>0</ixz>
          <iyy> 0.3375 </iyy>
          <iyz>0</iyz>
          <izz> 0.441667 </izz>
        </inertia>
      </inertial>
      <collision name='collision'>
        <geometry>
          <box>
            <size>0.9 0.5 0.5</size>
          </box>
        </geometry>
      </collision>
      <visual name='visual'>
        <pose>0 0 0.05 0 0 0</pose>
        <geometry>
          <mesh>
            <uri>model://pioneer2dx/meshes/chassis.dae</uri>
            <scale>0.9 0.5 0.5</scale>
          </mesh>
        </geometry>
      </visual>
      <collision name='caster_collision'>
        <pose>-0.15 0 -0.05 0 0 0</pose>
        <geometry>
          <sphere>
            <radius>.05</radius>
          </sphere>
        </geometry>
      </collision>
      <visual name='caster_visual'>
        <pose>-0.15 0 -0.05 0 0 0</pose>
            <mass>0.5</mass>
            <inertia>
              <ixx>0.0005</ixx>
              <ixy>0</ixy>
              <ixz>0</ixz>
              <iyy>0.0005</iyy>
              <iyz>0</iyz>
              <izz>0.0005</izz>
            </inertia>
        <geometry>
          <sphere>
            <radius>.05</radius>
          </sphere>
        </geometry>
      </visual>
    </link>

    <link name="left_wheel">
      <pose>0.1 0.13 0.1 0 1.5707 1.5707</pose>
      <inertial>
        <mass>1</mass>
        <inertia>
          <ixx>0.002708</ixx>
          <ixy>0</ixy>
          <ixz>0</ixz>
          <iyy>0.002708</iyy>
          <iyz>0</iyz>
          <izz>0.005</izz>
        </inertia>
      </inertial>
      <collision name="collision">
        <geometry>
          <cylinder>
            <radius>0.1</radius>
            <length>0.05</length>
          </cylinder>
        </geometry>
      </collision>
      <visual name="visual">
        <geometry>
          <cylinder>
            <radius>0.1</radius>
            <length>0.05</length>
          </cylinder>
        </geometry>
      </visual>
    </link>
    <link name="right_wheel">
      <pose>0.1 -0.13 0.1 0 1.5707 1.5707</pose>
      <inertial>
        <mass>1</mass>
        <inertia>
          <ixx>0.002708</ixx>
          <ixy>0</ixy>
          <ixz>0</ixz>
          <iyy>0.002708</iyy>
          <iyz>0</iyz>
          <izz>0.005</izz>
        </inertia>
      </inertial>
      <collision name="collision">
        <geometry>
          <cylinder>
            <radius>0.1</radius>
            <length>0.05</length>
          </cylinder>
        </geometry>
      </collision>
      <visual name="visual">
        <geometry>
          <cylinder>
            <radius>0.1</radius>
            <length>0.05</length>
          </cylinder>
        </geometry>
      </visual>
    </link>
    <joint type="revolute" name="left_wheel_hinge">
      <child>left_wheel</child>
      <parent>chassis</parent>
      <axis>
        <xyz>0 1 0</xyz>
        <limit>
          <lower>-1.79769e+308</lower>    <!--negative infinity-->
          <upper>1.79769e+308</upper>     <!--positive infinity-->
        </limit>
      </axis>
    </joint>
    <joint type="revolute" name="right_wheel_hinge">
      <child>right_wheel</child>
      <parent>chassis</parent>
      <axis>
        <xyz>0 1 0</xyz>
        <limit>
          <lower>-1.79769e+308</lower>    <!--negative infinity-->
          <upper>1.79769e+308</upper>     <!--positive infinity-->
        </limit>
      </axis>
    </joint>

    
    <link name="laser_link">
      <inertial>
        <mass>0.25</mass>
        <inertia>
          <ixx>0.000045</ixx>
          <ixy>0</ixy>
          <ixz>0</ixz>
          <iyy>0.000045</iyy>
          <iyz>0</iyz>
          <izz>0.000055</izz>
        </inertia>
      </inertial>
      <pose>0.15 0 0.3 0 0 0</pose>
      <visual name="visual">
        <geometry>
          <mesh>
            <uri>model://hokuyo/meshes/hokuyo.dae</uri>
          </mesh>
        </geometry>
      </visual>
      <collision name="collision-base">
        <pose>0 0 -0.0145 0 0 0</pose>
        <geometry>
          <box>
            <size>0.05 0.05 0.041</size>
          </box>
        </geometry>
      </collision>
      <collision name="collision-top">
        <pose>0 0 0.0205 0 0 0</pose>
        <geometry>
          <cylinder>
            <radius>0.021</radius>
            <length>0.029</length>
          </cylinder>
        </geometry>
      </collision>
      <sensor name="laser" type="ray">
        <pose>0.01 0 0.0175 0 -0 0</pose>
        <ray>
          <scan>
            <horizontal>
              <samples>340</samples>
              <resolution>1</resolution>
              <min_angle>-2.26889</min_angle>
              <max_angle>2.268899</max_angle>
            </horizontal>
          </scan>
          <range>
            <min>0.08</min>
            <max>10</max>
            <resolution>0.05</resolution>
          </range>
        </ray>
        <always_on>1</always_on>
        <update_rate>10</update_rate>
        <visualize>true</visualize>

        <plugin name='laser' filename='libgazebo_ros_ray_sensor.so'>
          <ros>
            <namespace>/en613</namespace>
            <argument>~/out:=scan</argument>
          </ros>
          <frame_name>laser_link</frame_name>
          <output_type>sensor_msgs/LaserScan</output_type>
        </plugin>
      </sensor>
    </link>

    <joint type="fixed" name="laser_joint">
      <child>laser_link</child>
      <parent>chassis</parent>
      <origin>0 0 0.03 0 0 0</origin>
    </joint>

    <plugin
        filename="libgazebo_ros_diff_drive.so"
        name="gazebo_ros_diff_drive">
        <ros>
          <namespace>/en613</namespace>  <!-- Changed to match your spawn argument -->
        </ros>
        <left_joint>left_wheel_hinge</left_joint>
        <right_joint>right_wheel_hinge</right_joint>
        <wheel_separation>0.26</wheel_separation>
        <wheel_diameter>0.2</wheel_diameter>
        <max_wheel_acceleration>1.0</max_wheel_acceleration>
        <max_wheel_torque>20</max_wheel_torque>
        <update_rate>10</update_rate>
        <command_topic>cmd_vel</command_topic>
        <odometry_topic>odom</odometry_topic>
        <odometry_frame>odom</odometry_frame>
        <robot_base_frame>chassis</robot_base_frame>
        <publish_wheel_joint_state>true</publish_wheel_joint_state>
    </plugin>

  </model>
</sdf>
