<?xml version="1.0"?>
<robot name="rockman">

  <material name="red">
    <color rgba="0.8 0 0 0.8"/>
  </material>
  <material name="blue">
    <color rgba="0 0 0.8 0.8"/>
  </material>
  <material name="black">
    <color rgba="0 0 0 0.8"/>
  </material>
  <material name="white">
    <color rgba="1 1 1 0.8"/>
  </material>


  <link name="chassis">
    <visual>
      <geometry>
        <box size="0.825 0.825  0.075"/>
      </geometry>
      <material name="white"/>
    <origin rpy="0 0 1.5707" xyz="0 0 0"/>
    </visual>
  </link>

  <link name="right_wheel">
    <visual>
      <geometry>
        <cylinder length="0.05" radius ="0.4"/>
      </geometry>
      <material name="red"/>
    </visual>
  </link>

  <joint name="chassis_to_right_wheel" type="continuous">
    <parent link="chassis"/>
    <child link="right_wheel"/>
    <origin rpy="-1.5707 0 0" xyz="0 -0.4375 0"/>
    <axis xyz="0 0 1"/> 
  </joint>

  <link name="left_wheel">
    <visual>
      <origin rpy="0 0 0" xyz="0 0 0"/>
      <geometry>
        <cylinder length="0.05" radius ="0.4"/>
      </geometry>
      <material name="blue"/>
    </visual>
  </link>

  <joint name="chassis_to_left_wheel" type="continuous">
    <parent link="chassis"/>
    <child link="left_wheel"/>
    <origin rpy="-1.5707 0 0" xyz="0 0.4375 0"/>
    <axis xyz="0 0 1"/> 
  </joint>

  <link name="lidar_dome">
    <visual>
      <geometry>
        <sphere radius="0.03125"/>
      </geometry>
      <material name="black"/>
    </visual>
  </link>

  <joint name="chassis_to_lidar_dome" type="fixed">
    <parent link="chassis"/>
    <child link="lidar_dome"/>
    <origin rpy="0 0 0" xyz="0.3 0 0.0375"/>
  </joint>
</robot>
